Traceback (most recent call last):
  File "/opt/anaconda3/envs/jupyterbook/lib/python3.10/site-packages/jupyter_cache/executors/utils.py", line 51, in single_nb_execution
    executenb(
  File "/opt/anaconda3/envs/jupyterbook/lib/python3.10/site-packages/nbclient/client.py", line 1204, in execute
    return NotebookClient(nb=nb, resources=resources, km=km, **kwargs).execute()
  File "/opt/anaconda3/envs/jupyterbook/lib/python3.10/site-packages/nbclient/util.py", line 84, in wrapped
    return just_run(coro(*args, **kwargs))
  File "/opt/anaconda3/envs/jupyterbook/lib/python3.10/site-packages/nbclient/util.py", line 62, in just_run
    return loop.run_until_complete(coro)
  File "/opt/anaconda3/envs/jupyterbook/lib/python3.10/asyncio/base_events.py", line 649, in run_until_complete
    return future.result()
  File "/opt/anaconda3/envs/jupyterbook/lib/python3.10/site-packages/nbclient/client.py", line 663, in async_execute
    await self.async_execute_cell(
  File "/opt/anaconda3/envs/jupyterbook/lib/python3.10/site-packages/nbclient/client.py", line 965, in async_execute_cell
    await self._check_raise_for_error(cell, cell_index, exec_reply)
  File "/opt/anaconda3/envs/jupyterbook/lib/python3.10/site-packages/nbclient/client.py", line 862, in _check_raise_for_error
    raise CellExecutionError.from_cell_and_msg(cell, exec_reply_content)
nbclient.exceptions.CellExecutionError: An error occurred while executing the following cell:
------------------
import numpy as np
male_vec=[]
for i,j in zip(male_list,female_list):
    male_vec.append(model[i]-model[j])
male_vec=np.array(male_vec)
male_vec=np.mean(male_vec,axis=0)
------------------

[0;31m---------------------------------------------------------------------------[0m
[0;31mNameError[0m                                 Traceback (most recent call last)
Cell [0;32mIn[2], line 4[0m
[1;32m      2[0m male_vec[38;5;241m=[39m[]
[1;32m      3[0m [38;5;28;01mfor[39;00m i,j [38;5;129;01min[39;00m [38;5;28mzip[39m(male_list,female_list):
[0;32m----> 4[0m     male_vec[38;5;241m.[39mappend([43mmodel[49m[i][38;5;241m-[39mmodel[j])
[1;32m      5[0m male_vec[38;5;241m=[39mnp[38;5;241m.[39marray(male_vec)
[1;32m      6[0m male_vec[38;5;241m=[39mnp[38;5;241m.[39mmean(male_vec,axis[38;5;241m=[39m[38;5;241m0[39m)

[0;31mNameError[0m: name 'model' is not defined
NameError: name 'model' is not defined

