Traceback (most recent call last):
  File "/home/lyuzeyu/anaconda3/lib/python3.10/site-packages/jupyter_cache/executors/utils.py", line 58, in single_nb_execution
    executenb(
  File "/home/lyuzeyu/anaconda3/lib/python3.10/site-packages/nbclient/client.py", line 1204, in execute
    return NotebookClient(nb=nb, resources=resources, km=km, **kwargs).execute()
  File "/home/lyuzeyu/anaconda3/lib/python3.10/site-packages/nbclient/util.py", line 84, in wrapped
    return just_run(coro(*args, **kwargs))
  File "/home/lyuzeyu/anaconda3/lib/python3.10/site-packages/nbclient/util.py", line 62, in just_run
    return loop.run_until_complete(coro)
  File "/home/lyuzeyu/anaconda3/lib/python3.10/asyncio/base_events.py", line 649, in run_until_complete
    return future.result()
  File "/home/lyuzeyu/anaconda3/lib/python3.10/site-packages/nbclient/client.py", line 663, in async_execute
    await self.async_execute_cell(
  File "/home/lyuzeyu/anaconda3/lib/python3.10/site-packages/nbclient/client.py", line 965, in async_execute_cell
    await self._check_raise_for_error(cell, cell_index, exec_reply)
  File "/home/lyuzeyu/anaconda3/lib/python3.10/site-packages/nbclient/client.py", line 862, in _check_raise_for_error
    raise CellExecutionError.from_cell_and_msg(cell, exec_reply_content)
nbclient.exceptions.CellExecutionError: An error occurred while executing the following cell:
------------------
class NeuralNetwork(nn.Module):
    def __init__(self, n_in, n_units_1, n_units_2, n_out):
        super(NeuralNetwork, self).__init__()
        self.l1 = nn.Linear(n_in, n_units_1)      # First hidden layer
        self.l2 = nn.Linear(n_units_1, n_units_2) # Second hidden layer
        self.l3 = nn.Linear(n_units_2, n_out)     # Output layer

    def forward(self, x):
        h1 = F.relu(self.l1(x))
        h2 = F.relu(self.l2(h1))
        y = F.log_softmax(self.l3(h2), dim=1)
        return y
------------------

[0;31m---------------------------------------------------------------------------[0m
[0;31mNameError[0m                                 Traceback (most recent call last)
Cell [0;32mIn[5], line 1[0m
[0;32m----> 1[0m [38;5;28;01mclass[39;00m [38;5;21;01mNeuralNetwork[39;00m([43mnn[49m[38;5;241m.[39mModule):
[1;32m      2[0m     [38;5;28;01mdef[39;00m [38;5;21m__init__[39m([38;5;28mself[39m, n_in, n_units_1, n_units_2, n_out):
[1;32m      3[0m         [38;5;28msuper[39m(NeuralNetwork, [38;5;28mself[39m)[38;5;241m.[39m[38;5;21m__init__[39m()

[0;31mNameError[0m: name 'nn' is not defined
NameError: name 'nn' is not defined

